# Final Log Analysis - Why Logs Don't Appear

## üîç Root Cause Identified

The diagnostic logs (`[CONTEXT_CHECK]`, `[BINANCE_SELL_REQUEST]`, `[ERROR_CAUGHT]`) are **not appearing** because:

### The Problem Chain:

1. **`queueFunctionCall` throws errors** - When Binance returns 400, `apiQueue.jsx` throws the error (line 1622)
2. **Error bubbles up** - The error propagates from `queueFunctionCall` ‚Üí `attemptSell` ‚Üí `_executeBinanceMarketSellOrder`
3. **Missing try-catch in `attemptSell`** - There's no try-catch around `queueFunctionCall`, so we can't see the error structure
4. **Outer catch may not be reached** - If the error format doesn't match what we expect, the outer catch might not handle it correctly

## ‚úÖ What I've Fixed

### 1. Added Try-Catch in `attemptSell`
```javascript
try {
    const response = await queueFunctionCall(...);
    // Handle success
} catch (queueError) {
    // Log full error details
    console.log(`[QUEUE_ERROR_CAUGHT_IN_ATTEMPTSELL]`, queueError);
    throw queueError; // Re-throw for outer catch
}
```

This will show us:
- ‚úÖ The exact error structure
- ‚úÖ Error message, code, response status
- ‚úÖ Whether `isClosingContext` is set correctly
- ‚úÖ Why the outer catch block might not be working

### 2. Enhanced Logging Points

Now we'll see logs at these critical points:
1. **Before API call**: `[BINANCE_SELL_REQUEST] About to call queueFunctionCall...`
2. **On error from queue**: `[QUEUE_ERROR_CAUGHT_IN_ATTEMPTSELL]` (NEW)
3. **In outer catch**: `[ERROR_CAUGHT]` (if it reaches there)

## üéØ Expected Behavior After Fix

When you run again, you should see:

### Scenario A: Error caught in `attemptSell`
```
[BINANCE_SELL_REQUEST] About to call queueFunctionCall...
[QUEUE_ERROR_CAUGHT_IN_ATTEMPTSELL] Error caught from queueFunctionCall:
[QUEUE_ERROR_CAUGHT_IN_ATTEMPTSELL] Error message: Account has insufficient balance...
[QUEUE_ERROR_CAUGHT_IN_ATTEMPTSELL] isClosingContext=true
[ERROR_CAUGHT] Error caught in _executeBinanceMarketSellOrder...
[ORDER_HISTORY_CHECK] START: ...
```

### Scenario B: Error format issue
```
[BINANCE_SELL_REQUEST] About to call queueFunctionCall...
[QUEUE_ERROR_CAUGHT_IN_ATTEMPTSELL] Error caught (but wrong format)
[ERROR_ANALYSIS] isInsufficient=false (because error format didn't match)
```

## üîß Next Steps

1. **Run the app again** and check for `[QUEUE_ERROR_CAUGHT_IN_ATTEMPTSELL]` logs
2. **Check if `isClosingContext=true`** in the logs
3. **Verify error format** - see what the actual error structure is
4. **Confirm if outer catch runs** - see if `[ERROR_CAUGHT]` appears

These logs will definitively show us what's happening! üîç

